Ah não! Algo deu errado e lá vem o Bugginho de novo.

A issue de número [#{{ issue.number }} - {{ issue.title }}]({{ issue.html_url|raw }}), do repositorio [{{ repositorio.name }}]({{ repositorio.html_url|raw}}) acaba de ser reaberta pelo usuário [@{{ user.login }}]({{ user.html_url|raw }})
----